Workbook
Name _a100000: '[1]IE & BS'!#REF!
Name _a100000: '[1]IE & BS'!#REF!
Name _a100000: '[1]IE & BS'!#REF!
Name _a100000: '[1]IE & BS'!#REF!
Name a: [2]BF_1!$DM$1:$EI$119
Name aaa: [2]BF_1!$EV$1:$EZ$31
Name ChallanDatabase: [3]Challan!$A$7:$S$58
Name ChallanDatabaseTotal: [3]Challan!$A$7:$U$58
Name ChallanSrnoList: [3]Challan!$A$7:$A$57
Name check: #REF!
Name check: #REF!
Name check: #REF!
Name nSkip: 15

Sheet COMPUTATION 
A1: TALEP ALI
A2: C/O : SALEH UDDIN , VILL : NAGAJAN
A3: P.O : KHARUPETIA , DIST. : DARRANG
A4: STATE : ASSAM, PIN : 784115
B6: PAN | C6: BSBPA6931N | D6: Bank & Branch | E6: STATE BANK OF INDIA | G6: AY. YEAR | H6: 2025-2026
B7: Bank A/c | C7: 35940302898 | D7: FATHER | E7: SALEH UDDIN | G7: FY. YEAR | H7: 2024-2025
B8: IFSC | C8: SBIN0002077 | D8: DOB | E8: 18.06.1997 | G8: Status | H8: Individual
B10: COMPUTATION OF INCOME
B12: Particulars | F12: Details | H12: Amount(`)
B14: INCOME FROM PROFESSION
B15: As per Profit & loss A/c 44AD | H15: =+'PL New Format'!D34 -> 694638
B17: INCOME FROM OTHER SOURCES
B18: Bank Interest | H18: 79
F20: Gross Total Income | H20: =SUM(H14:H19) -> 694717
F21: Total Income | H21: =H20 -> 694717
F22: less: Deduction:
F23: U/s 80C
F24: Insurance Premium | H24: 0
F25: Children Edu. Fee | H25: 0
F26: U/S 80TTA | H26: 0
H27: =H21-SUM(H24:H26) -> 694717
F28: Round Off U/s 288A | H28: =ROUND((H27/10),0)*10 -> 694720
F29: Basic Tax | H29: =ROUND((IF(H28<=300000,0,IF(H28<=700000,(H28-300000)*0.05,IF(H28<=1000000,20000+(H28-700000)*0.1,IF(H28<=1200000,50000+(H28-1000000)*0.15,IF(H28<=1500000,80000+(H28-1200000)*0.2,140000+(H28-1500000)*0.3)))))),0) -> 19736
F30: Less: U/s 87A | H30: =IF(AND(H28<=700000),MIN(H29,25000),0) -> 19736
F31: Tax After Rebate | H31: =H29-H30 -> 0
F32: Less: Marginal Relief | H32: 0
H33: =H31-H32 -> 0
F34: Add: HEC @ 4 % | H34: =ROUND((H31*0.04),0) -> 0
H35: =H31+H34 -> 0
F36: Add: Interest u/s 234A/B/C | H36: 0 | I36: =600*0.06 -> 36
F37: Add: Late Fee U/s 234F | H37: 0
F38: Round off u/s 288B | H38: =ROUND(((SUM(H35:H37))/10),0)*10 -> 0
F39: Less: TDS | H39: =+'Balance Sheet '!D42 -> 0
F40: less: Amount Paid U/s 140A | H40: 0
F41: Tax Payable (Refundable) | H41: =H38-H39-H40 -> 0
B43: Note :-
B44: Gross Receipt | D44: =+Notes!E53 -> 28241584
B45: Total Expenses | D45: =D44-D46 -> 27546946
B46: Net Profit | D46: =H15 -> 694638 | E46: =D46/D44 -> 0.024596283

Sheet Balance Sheet 
A1: TALEP VEGETABLE SHOP
A2: Prop:-
A3: =+'COMPUTATION '!A1:H1 -> TALEP ALI
A4: =+'COMPUTATION '!A2:H2 -> C/O : SALEH UDDIN , VILL : NAGAJAN
A5: =+'COMPUTATION '!A3:H3 -> P.O : KHARUPETIA , DIST. : DARRANG
A6: =+'COMPUTATION '!A4:H4 -> STATE : ASSAM, PIN : 784115
A8: BALANCE SHEET AS ON 31ST MARCH 2025
B9: Particulars | C9: Note | D9: As at 31st March 2025 | E9: As at 31st March 2024 | F9: As at 31st March 2022 | G9: Actual Change | H9: % of Change | L9: =O9*0.06 -> 632126.04 | O9: 10535434
A10: I | B10: SOURCES OF FUNDS | L10: =O10*0.08 -> 87200 | O10: 1090000
A11: (a) | B11: Owners Fund
A12: (i) | B12: Capital A/c | C12: 1 | D12: =+Notes!E14 -> 1360208 | E12: =+Notes!F14 -> 1065570 | F12: 100000 | G12: =D12-E12 -> 294638 | H12: =G12/E12 -> 0.27650741
D13: =SUM(D12:D12) -> 1360208 | E13: =SUM(E12:E12) -> 1065570 | F13: =SUM(F12:F12) -> 100000 | G13: =D13-E13 -> 294638 | H13: =G13/E13 -> 0.27650741
A14: 2 | B14: Non-current liabilities
A15: (a) | B15: Long-term borrowings | C15: 3 | D15: =+Notes!E23 -> 723999 | E15: 0 | F15: 0 | G15: =D15-E15 -> 723999
A16: (b ) | B16: Other long-term liabilities | D16: 0 | E16: 0 | F16: 0 | G16: =D16-E16 -> 0
A17: (c ) | B17: Long-term provisions | D17: 0 | E17: 0 | F17: 0 | G17: =D17-E17 -> 0
D18: =SUM(D15:D17) -> 723999 | E18: =SUM(E15:E17) -> 0 | F18: =SUM(F15:F17) -> 0 | G18: =D18-E18 -> 723999
A19: 3 | B19: Current Liabilities | G19: =D19-E19 -> 0
A20: (a) | B20: Short-term borrowings | C20: 4 | D20: =+Notes!E27 -> 795461 | E20: 0 | F20: 0 | G20: =D20-E20 -> 795461
A21: (b) | B21: Trade payables | D21: 0 | F21: 0 | G21: =D21-E21 -> 0
A22: (i) | B22: Total outstanding dues of micro, small and medium enterprises | D22: 22458 | E22: 45620 | F22: 0 | G22: =D22-E22 -> -23162
A23: (ii) | B23: Total outstanding dues of creditors other than micro, small and medium enterprises | D23: 0 | E23: 0 | F23: 0 | G23: =D23-E23 -> 0
A24: (c) | B24: Other current liabilities | D24: 0 | E24: 0 | F24: 0 | G24: =D24-E24 -> 0
A25: (d) | B25: Short-term provisions | C25: 5 | D25: =+Notes!E31 -> 10000 | E25: 0 | F25: 11000 | G25: =D25-E25 -> 10000
D26: =SUM(D20:D25) -> 827919 | E26: =SUM(E20:E25) -> 45620 | F26: =SUM(F20:F25) -> 11000 | G26: =D26-E26 -> 782299 | H26: =G26/E26 -> 17.148159
B27: Total | D27: =D26+D18+D13 -> 2912126 | E27: =E13+E18+E26 -> 1111190 | F27: =F26+F18+F13 -> 111000 | G27: =D27-E27 -> 1800936 | H27: =G27/E27 -> 1.6207273
A28: II | B28: APPLICATION OF FUNDS | G28: =D28-E28 -> 0
A29: 1 | B29: Non-current assets | G29: =D29-E29 -> 0
A30: (a) | B30: Fixed Assets | C30: 2 | F30: 0 | G30: =D30-E30 -> 0
B31: Gross Book Value | D31: =+FA!H22 -> 42836 | E31: =32805+15660 -> 48465 | G31: =D31-E31 -> -5629 | H31: =G31/E31 -> -0.11614567
B32: Less : Depreciation | D32: =+FA!I22 -> 4950 | E32: 5630 | G32: =D32-E32 -> -680 | H32: =G32/E32 -> -0.12078153
B33: Net Book Value | D33: =D31-D32 -> 37886 | E33: =E31-E32 -> 42835 | F33: 0 | G33: =D33-E33 -> -4949 | H33: =G33/E33 -> -0.11553636
A34: (b) | B34: Non-current investments | D34: 0 | E34: 0 | F34: 0 | G34: =D34-E34 -> 0
A35: (c) | B35: Long Term Loans and Advances | D35: 0 | E35: 0 | F35: 0 | G35: =D35-E35 -> 0
A36: (d) | B36: Other non-current assets | C36: 6 | D36: =+Notes!E35 -> 0 | E36: 0 | F36: 0 | G36: =D36-E36 -> 0
D37: =D36 -> 0 | E37: =E36 -> 0 | F37: =SUM(F30:F36) -> 0 | G37: =D37-E37 -> 0 | H37: =G37/E37 -> #DIV/0!
A38: 2 | B38: Current Assets | G38: =D38-E38 -> 0
A39: (a) | B39: Current investments | D39: 0 | E39: 0 | F39: 0 | G39: =D39-E39 -> 0
A40: (b) | B40: Inventories | D40: =+Notes!E61 -> 2195620 | E40: =+Notes!F61 -> 698920 | F40: 0 | G40: =D40-E40 -> 1496700 | H40: =G40/E40 -> 2.1414468
A41: (c) | B41: Trade receivables | D41: 531410 | E41: 213460 | F41: 0 | G41: =D41-E41 -> 317950 | H41: =G41/E41 -> 1.4895062
...

Sheet PL New Format
A1: =+'Balance Sheet '!A1:E1 -> TALEP VEGETABLE SHOP
A2: =+'Balance Sheet '!A2:E2 -> Prop:-
A3: =+'Balance Sheet '!A3:E3 -> TALEP ALI
A4: =+'Balance Sheet '!A4:E4 -> C/O : SALEH UDDIN , VILL : NAGAJAN
A5: =+'Balance Sheet '!A5:E5 -> P.O : KHARUPETIA , DIST. : DARRANG
A6: =+'Balance Sheet '!A6:E6 -> STATE : ASSAM, PIN : 784115
A7: Statement of Profit and Loss for the year ended 31st March, 2025
B8: Particulars | C8: Note | D8: 31st March 2025 | E8: 31st March 2024
A9: I | B9: Revenue from operations | C9: 10 | D9: =Notes!E53 -> 28241584 | E9: =+Notes!F51 -> 6195510
A10: II | B10: Other Income | C10: 11 | E10: 0
A11: III | B11: Total Income (I+II) | D11: =D9+D10 -> 28241584 | E11: =E9+E10 -> 6195510
A13: IV | B13: Expenses:
A14: (a) | B14: Cost of goods sold | C14: 12 | D14: =+Notes!E62 -> 26920064 | E14: =+Notes!F62 -> 5402485
A15: (b) | B15: Employee benefits expense | C15: 13 | D15: =+Notes!E68 -> 150000 | E15: =+Notes!F68 -> 96000
A16: (c) | B16: Finance costs | C16: 14 | D16: =+Notes!E85 -> 165246 | E16: =+Notes!F85 -> 0
A17: (d) | B17: Depreciation and amortization expense | C17: 2 | D17: =+Notes!E18 -> 4950 | E17: =+Notes!F18 -> 5630
A18: (e) | B18: Other expenses | C18: 15 | D18: =+Notes!E79 -> 306686 | E18: =+Notes!F79 -> 192254
B19: Total expenses | D19: =SUM(D14:D18) -> 27546946 | E19: =SUM(E14:E18) -> 5696369
A20: V | B20: Profit/(loss) before exceptional and extraordinary items and tax (III- IV) | D20: =D11-D19 -> 694638 | E20: =E11-E19 -> 499141
A21: VI | B21: Exceptional items | D21: 0 | E21: 0
A22: VII | B22: Profit/(loss) before extraordinary items and tax (V-VI) | D22: =D20-D21 -> 694638 | E22: =E20-E21 -> 499141
A23: VIII | B23: Extraordinary Items | D23: 0 | E23: 0
A24: IX | B24: Profit before tax (VII-VIII) | D24: =D22-D23 -> 694638 | E24: =E22-E23 -> 499141
A25: X | B25: Tax expense:
A26: (a) | B26: Current tax | D26: 0 | E26: 0
A27: (b) | B27: Excess/ Short provision of tax relating to earlier years
A28: (c) | B28: Deferred tax charge/ (benefit) | D28: 0 | E28: 0
D29: =SUM(D26:D28) -> 0 | E29: =SUM(E26:E28) -> 0
A30: XI | B30: Profit/(Loss) for the period from continuing operations (IX-X) | D30: =D24-D29 -> 694638 | E30: =E24-E29 -> 499141
A31: XII | B31: Profit/(loss) from discontinuing operations | D31: 0 | E31: 0
A32: XIII | B32: Tax expense of discontinuing operations | D32: 0 | E32: 0
A33: XIV | B33: Profit/(loss) from discontinuing operations (after tax) (XII-XIII) | D33: =D31-D32 -> 0 | E33: =E31-E32 -> 0
A34: XV | B34: Profit/(Loss) for the year (XI+XIV) | D34: =D30+D33 -> 694638 | E34: =E30+E33 -> 499141
A37: =+'Balance Sheet '!A53 -> For ISHRAT JAHAN & ASSOCIATES
A38: =+'Balance Sheet '!A54 -> Chartered Accountants
A39: =+'Balance Sheet '!A55 -> FRN: 042976N
A41: =+'Balance Sheet '!A57 -> CA. Ishrat Jahan | D41: =+'Balance Sheet '!D57 -> For, Talep Vegetable Shop
A42: =+'Balance Sheet '!A58 -> (Proprietor) | D42: =+'Balance Sheet '!D58 -> Sd/-
A43: =+'Balance Sheet '!A59 -> Membership No.: 577705 | D43: =+'Balance Sheet '!D59 -> Talep Ali
A44: =+'Balance Sheet '!A60 -> Date: 22.09.2025 | D44: =+'Balance Sheet '!D60 -> Place : Kharupetia
...

Sheet FA
B1: =+'Balance Sheet '!A1 -> TALEP VEGETABLE SHOP
B2: =+'Balance Sheet '!A2 -> Prop:-
B3: =+'Balance Sheet '!A3 -> TALEP ALI
B4: =+'Balance Sheet '!A4 -> C/O : SALEH UDDIN , VILL : NAGAJAN
B5: =+'Balance Sheet '!A5 -> P.O : KHARUPETIA , DIST. : DARRANG
B6: =+'Balance Sheet '!A6 -> STATE : ASSAM, PIN : 784115
B7: Note (2) :
B8: FIXED ASSET SCHEDULE FOR THE YEAR ENDED 31.03.2025
B10: ASSETS | C10: GROSS BOLCK | I10: DEPRECIATION | J10: NET BLOCK
C11: BALANCE AS ON 01.04.2024 | D11: RATE OF DEPRECIATION | E11: ADDITION | G11: TOTAL PURCHASE | H11: TOTAL | J11: WDV AS ON 31.03.2025
E12: UPTO 03.10.2024 | F12: AFTER 03.10.2024
B13: BLOCK-I : 10%
B14: Furniture | C14: 29525 | D14: 0.1 | E14: 0 | F14: 0 | G14: =E14+F14 -> 0 | H14: =C14+G14 -> 29525 | I14: =ROUND(((C14+E14)*D14+F14*D14*0.5),0) -> 2953 | J14: =H14-I14 -> 26572
B16: BLOCK-II : 15%
B17: Plant & machinery | C17: 13311 | D17: 0.15 | E17: 0 | F17: 0 | G17: =E17+F17 -> 0 | H17: =C17+G17 -> 13311 | I17: =ROUND(((C17+E17)*D17+F17*D17*0.5),0) -> 1997 | J17: =H17-I17 -> 11314
B19: BLOCK-III : 40%
B20: Computer & Printer | C20: 0 | D20: 0.4 | E20: 0 | F20: 0 | G20: =E20+F20 -> 0 | H20: =C20+G20 -> 0 | I20: =ROUND(((C20+E20)*D20+F20*D20*0.5),0) -> 0 | J20: =H20-I20 -> 0
C22: =SUM(C14:C20) -> 42836 | E22: =SUM(E14:E20) -> 0 | F22: =SUM(F14:F20) -> 0 | G22: =SUM(G14:G20) -> 0 | H22: =SUM(H14:H20) -> 42836 | I22: =SUM(I14:I20) -> 4950 | J22: =SUM(J14:J20) -> 37886 | K22: =H22-I22 -> 37886 | L22: =J22-K22 -> 0
H26: =+'Balance Sheet '!D58 -> Sd/-
H27: =+'Balance Sheet '!D59 -> Talep Ali
H28: =+'Balance Sheet '!D60 -> Place : Kharupetia
H29: =+'Balance Sheet '!D61 -> Date : 22.09.2025

Sheet F.A. 
A1: ='Balance Sheet '!#REF! -> #REF!
A2: ='Balance Sheet '!#REF! -> #REF!
A4: Fixed Assets Chart
A5: For the Year Ending on 31 March 2020
A7: Sr. No. | B7: Assets | C7: Depreciation Rate | D7: Opening WDV | E7: Addition | F7: Deletion | G7: Total Value | H7: Depreciation Rate | I7: Depreciation Value | J7: Closing Balance
A9: 1 | B9: ='Balance Sheet '!B39 -> Current investments | C9: 0.15 | D9: 0 | G9: =D9+E9-F9 -> 0 | H9: 0.15 | I9: =G9*H9 -> 0 | J9: =ROUND(D9-I9,0) -> 0
A10: 2 | B10: Less Grants | C10: 0.15 | D10: 0 | G10: =D10+E10-F10 -> 0 | H10: 0.15 | I10: =G10*H10 -> 0 | J10: =ROUND(D10-I10,0) -> 0
B11: Total | C11: =C9-C10 -> 0 | D11: =SUM(D9:D10) -> 0 | E11: =E9-E10 -> 0 | F11: =F9-F10 -> 0 | G11: =ROUND(G9-G10,0) -> 0 | H11: =H9-H10 -> 0 | I11: =ROUND(I9-I10,0) -> 0 | J11: =ROUND(J9-J10,0) -> 0

Sheet Notes
A1: =+FA!B1 -> TALEP VEGETABLE SHOP
A2: =+FA!B2 -> Prop:-
A3: =+'Balance Sheet '!A3:H3 -> TALEP ALI
A4: =+'Balance Sheet '!A4:H4 -> C/O : SALEH UDDIN , VILL : NAGAJAN
A5: =+'Balance Sheet '!A5:H5 -> P.O : KHARUPETIA , DIST. : DARRANG
A6: =+'Balance Sheet '!A6:H6 -> STATE : ASSAM, PIN : 784115 | G6: Bank Name | H6: Deposit | I6: Bank Charge | J6: Int rec | K6: Int Pay | L6: Closing
G7: HDFC_582 | H7: 10967799 | I7: 894.1 | L7: 1950.32
A8: Sl. No | C8: Particulars | D8: Note No. | E8: 31.03.2025 | F8: 31.03.2024 | G8: HDFC_845_CC | H8: 8802718 | I8: 729.26 | K8: 95566
A9: 1 | C9: Capital Account | D9: 1 | G9: NORTH EAST | H9: 2650340 | I9: 619.5 | L9: 6555.25
C10: Opening Balance | E10: =+'Balance Sheet '!E13 -> 1065570 | F10: 863149 | G10: IPPB-363 | H10: 99073 | I10: 46.82 | L10: 18821.14
C11: Add: Profit During the year | E11: =+'PL New Format'!D34 -> 694638 | F11: =+'PL New Format'!E34 -> 499141 | G11: SBI-898 | H11: 895101 | I11: 214.76 | J11: 60 | L11: 4953.51
C12: Total (A) | E12: =SUM(E10:E11) -> 1760208 | F12: =F10+F11 -> 1362290 | G12: TOTAL | H12: =SUM(H7:H11) -> 23415031 | I12: =SUM(I7:I11) -> 2504.44 | J12: =SUM(J7:J9) -> 0 | K12: =SUM(K7:K11) -> 95566 | L12: =SUM(L7:L11) -> 32280.22
C13: Less: Drawings | E13: 400000 | F13: 296720
C14: Capital As on 31.03.2025 (C=A-B) | E14: =E12-E13 -> 1360208 | F14: =F12-F13 -> 1065570
A16: 2 | C16: Depreciation & Amortization | D16: 2
C17: Gross Book Value | E17: =+FA!C22 -> 42836 | F17: =32805+15660 -> 48465
C18: Less: Depreciation | E18: =+FA!I22 -> 4950 | F18: 5630
C19: Net Book Value | E19: =E17-E18 -> 37886 | F19: =F17-F18 -> 42835
A21: 3 | C21: Long Term Borrowings | D21: 3
C22: Bajaj - PZ10PBL11733786 | E22: 723999 | F22: 0
E23: =E22 -> 723999 | F23: =F22 -> 0
A25: 4 | C25: Short Term Borrowings | D25: 4
C26: HDFC - 50200094027845 | E26: =ROUND((795460.96),0) -> 795461 | F26: 0
E27: =E26 -> 795461 | F27: =F26 -> 0
A29: 5 | C29: Short Term Provision | D29: 5
C30: Audit Fee Payable | E30: 10000 | F30: 0
E31: =E30 -> 10000 | F31: =F30 -> 0
A33: 6 | C33: Non-Current Assets
C34: Secrity Deposits | D34: 6 | E34: 0 | F34: 0
E35: =E34 -> 0 | F35: =F34 -> 0
C37: Balances with Revenue Authority
A38: 7 | C38: TDS | D38: 7 | E38: 0 | F38: 0
C39: ITC | E39: 0 | F39: 0
E40: =E38+E39 -> 0 | F40: =F38+F39 -> 0
G41: Deposits | H41: Bank Charge
A42: 8 | C42: Cash at Bank | D42: 8
C43: Hdfc A/c - 50200066184582 | E43: =ROUND((L7),0) -> 1950 | F43: 0 | G43: =10391822+3836715 -> 14228537 | H43: 765
C44: North East A/c - 10190000669264 | E44: =ROUND((L9),0) -> 6555 | F44: 0
C45: SBI A/c - 35940302898 | E45: =ROUND((L11),0) -> 4954 | F45: 0
C46: India Post Payments Bank A/c - 5510101363 | E46: =ROUND((L10),0) -> 18821 | F46: 0
...

Sheet Accounting Policies
A1: =+'Balance Sheet '!A1:H1 -> TALEP VEGETABLE SHOP
A2: =+'Balance Sheet '!A2:H2 -> Prop:-
A3: =+'Balance Sheet '!A3:H3 -> TALEP ALI
B4: =+FA!B4 -> C/O : SALEH UDDIN , VILL : NAGAJAN
B5: =+FA!B5 -> P.O : KHARUPETIA , DIST. : DARRANG
B6: =+FA!B6 -> STATE : ASSAM, PIN : 784115
B7: Annexure -1
B9: 1. Basis of Preparation of Financial Statements
B10: The financial statements have been prepared under the historical cost convention on an accrual basis of accounting and in accordance with the applicable Accounting Standards as prescribed under the Companies (Accounting Standards) Rules, 2021 and the relevant provisions of the Companies Act, 2013.
B11: 2. Use of Estimates
B12: The preparation of financial statements in conformity with Indian GAAP requires management to make estimates and assumptions that affect the reported amounts of assets, liabilities, revenues, and expenses. Actual results could differ from these estimates. Any revision to accounting estimates is recognized prospectively
B13: 3. Revenue Recognition
B14: Revenue is recognized to the extent it is probable that the economic benefits will flow to the company and the revenue can be reliably measured: - Sale of goods is recognized on transfer of significant risks and rewards of ownership. - Income from services is recognized as per the terms of the contract. - Interest income is recognized on a time proportion basis. - Dividend income is recognized when the right to receive payment is established.
B15: 4. Property, Plant and Equipment (PPE)
B16: Tangible fixed assets are stated at cost, net of accumulated depreciation and impairment losses, if any. The cost comprises the purchase price and directly attributable costs for bringing the asset to its working condition. Depreciation is provided on a [Straight Line Method / Written Down Value Method] as per the useful life specified in Schedule II to the Companies Act, 2013.
B17: 5. Inventories
B18: Inventories are valued at the lower of cost or net realizable value. Cost of inventories is determined on FIFO basis. Cost includes all expenses incurred in bringing the inventory to its present location and condition
B19: 6. Taxes on Income
... B25: Cash and cash equivalents include cash in hand, bank balances, demand deposits, and other short-term highly liquid investments with original maturities of three months or less.
D33: =+FA!H26 -> Sd/-
D34: =+FA!H27 -> Talep Ali
D35: =+FA!H28 -> Place : Kharupetia
D36: =+FA!H29 -> Date : 22.09.2025

Sheet Loan Schedule 
A1: =+'Balance Sheet '!#REF! -> #REF!
A2: =+'Balance Sheet '!#REF! -> #REF!
A3: =+'Balance Sheet '!#REF! -> #REF!
A4: =+'Balance Sheet '!A4:H4 -> C/O : SALEH UDDIN , VILL : NAGAJAN
A5: =+'Balance Sheet '!A5:H5 -> P.O : KHARUPETIA , DIST. : DARRANG
A6: =+'Balance Sheet '!A6:H6 -> STATE : ASSAM, PIN : 784115
A8: Statement of Loan & Closing Balance As on 31.03.2025
A10: Loan Amount | C10: 600000
A11: Interest Rate | C11: =0.16504/12 -> 0.013753333 | D11: Monthly
A12: Tenure | C12: 180 | D12: Month
A13: EMI | C13: =ROUND((PMT(C11,C12,-C10)),0) -> 9024
A15: Sl. No | B15: Month | C15: Year | D15: Opining Balance | E15: Interest | F15: Total Amount | G15: Emi | H15: Closing Balance
A16: 1 | B16: August | C16: 2024 | D16: =C10 -> 600000 | E16: =ROUND((D16*$C$11),0) -> 8252 | F16: =D16+E16 -> 608252 | G16: 21052 | H16: =F16-G16 -> 587200
A17: =A16+1 -> 2 | B17: September | C17: 2024 | D17: =H16 -> 587200 | E17: =ROUND((D17*$C$11),0) -> 8076 | F17: =E17+D17 -> 595276 | G17: 21052 | H17: =F17-G17 -> 574224
A18: 3 | B18: Oct | C18: 2024 | D18: =H17 -> 574224 | E18: =ROUND((D18*$C$11),0) -> 7897 | F18: =E18+D18 -> 582121 | G18: 21052 | H18: =F18-G18 -> 561069
A19: 4 | B19: Nov | C19: 2024 | D19: =H18 -> 561069 | E19: =ROUND((D19*$C$11),0) -> 7717 | F19: =E19+D19 -> 568786 | G19: 21052 | H19: =F19-G19 -> 547734
A20: 5 | B20: December | C20: 2024 | D20: =H19 -> 547734 | E20: =ROUND((D20*$C$11),0) -> 7533 | F20: =E20+D20 -> 555267 | G20: 21052 | H20: =F20-G20 -> 534215
A21: 6 | B21: January | C21: 2024 | D21: =H20 -> 534215 | E21: =ROUND((D21*$C$11),0) -> 7347 | F21: =E21+D21 -> 541562 | G21: 21052 | H21: =F21-G21 -> 520510
A22: 7 | B22: Feb | C22: 2024 | D22: =H21 -> 520510 | E22: =ROUND((D22*$C$11),0) -> 7159 | F22: =E22+D22 -> 527669 | G22: 21052 | H22: =F22-G22 -> 506617
A23: =A22+1 -> 8 | B23: March | C23: 2024 | D23: =H22 -> 506617 | E23: =ROUND((D23*$C$11),0) -> 6968 | F23: =E23+D23 -> 513585 | G23: 21052 | H23: =F23-G23 -> 492533
A24: Total | E24: =SUM(E16:E23) -> 60949 | G24: =SUM(G16:G23) -> 168416
C27: =+[4]FA!H24 -> Sd/-
C28: =+[4]FA!H25 -> Suruj Ali
C29: =+[4]FA!H26 -> Place : Kharupetia
C30: =+[4]FA!H27 -> Date : 19.06.2025
